Workbook
Name _5x5__ages: #REF!
Name _5x5__ages: #REF!
Name AthleteIDs: Athletes!$A$2:$A$40
Name BarWeight: [2]Questions!$C$7
Name BBBPercentage: [2]Questions!$C$11
Name Category: #REF!
Name Category: #REF!
Name DayFour: [2]Questions!$R$11
Name DayOne: [2]Questions!$R$8
Name DayThree: [2]Questions!$R$10
Name DayTwo: [2]Questions!$R$9
Name EventsList: Lists!$B$2:$B$5
Name ExFour: [2]Questions!$C$18
Name ExOne: [2]Questions!$C$15
Name ExThree: [2]Questions!$C$17
Name ExTwo: [2]Questions!$C$16
Name IncrFour: [2]Questions!$C$31
Name IncrOne: [2]Questions!$C$28
Name IncrThree: [2]Questions!$C$30
Name IncrTwo: [2]Questions!$C$29
Name LiftsList: Lists!$F$2:$F$16
Name MaxNames: 'Max Master'!$B$4:$B$43
Name Names: #REF!
Name Names: #REF!
Name PERCENTAGES: [3]Categories!#REF!
Name RMFour: [2]Questions!$I$24
Name RMOne: [2]Questions!$I$21
Name RMThree: [2]Questions!$I$23
Name RMTwo: [2]Questions!$I$22
Name Rounding: [2]Questions!$C$9
Name SetRep: [3]Categories!$R$3:$R$59
Name SetxRep: [3]Categories!#REF!
Name StatusList: Lists!$D$2:$D$4
Name TblSetRep: [3]Categories!#REF!
Name TeamsList: Lists!$A$2:$A$7
Name TEST1: #REF!
Name TEST1: #REF!
Name WeightFormat: [2]Questions!$E$8
Name YNList: Lists!$C$2:$C$3

Sheet Instructions
B1: THROWERS R US — ANNUAL PLAN & ATHLETE MONITORING SYSTEM
B2: 21st 'Coming of Age' Season and beyond | H. Michael Vassell | jamthrows@gmail.com
B5: HOW THIS WORKBOOK WORKS
B6: This file is the single database for your throws programme. Upload it to Google Drive, open it as a Google Sheet, and connect it to AppSheet. Athletes submit weekly results from their phones through the AppSheet app; the data lands in the 'Weekly Results' tab and every report updates automatically.
B8: TAB GUIDE
B9: 1. Athletes — the master roster. One row per thrower, tagged by team, with baseline numbers (start-of-season throw distance, squat, bench, power clean) and PBs. Sample athletes are included — replace with your real roster.
B10: 2. Annual Plan — a 52-week periodised season template (GPP → SPP → Pre-Comp → Competition → Peak → Nationals → Transition → Recovery). Change the Season Start date at the top and every week re-dates itself. Edit phases/focus to suit each group.
B11: 3. Meet Schedule — update this weekly as fixtures are confirmed. It feeds the meet dropdown in AppSheet so athletes can tag competition results.
B12: 4. Weekly Results — the data table AppSheet writes to. One row per athlete per week: best throw plus top sets for squat, bench and power clean, RPE, and whether it was a meet result. Sample rows included for demonstration — delete once live.
B13: 5. Athlete Report — pick any Athlete ID from the dropdown to see this week vs last week for every metric, with ▲/▼ improvement flags, comparison to baseline, season best, and a 16-week trend table.
B14: 6. Monthly Summary — pick an athlete and see best/average performance month by month across the season.
B15: 7. Squad Overview — the annual report: every athlete's baseline vs season best, gains in metres and %, best lifts, last log date, and an overall Improving/Declining flag. Sortable by team.
... B43: • Workflow: test maxes → enter in Max Master → athletes' programmes generate → athletes log best working sets weekly via AppSheet → reports show whether the throws are responding to the lifting.

Sheet Lists
A1: Teams | B1: Events | C1: Y/N | D1: Status | E1: Phases | F1: Core Lifts
A2: Excelsior High | B2: Shot Put | C2: Y | D2: Active | E2: General Preparation (GPP) | F2: WIDE BENCH PRESS
A3: UTech | B3: Discus | C3: N | D3: Injured | E3: Specific Preparation (SPP) | F3: BACK PRESS
A4: Throwers R Us | B4: Javelin | D4: Inactive | E4: Pre-Competition | F4: SQUATS
A5: ACE Track Club | B5: Hammer | E5: Competition 1 | F5: CLEANS
A6: UWI | E6: Peak / Championships | F6: SNATCH
A7: Other | E7: Competition 2 / Nationals | F7: DEADLIFTS
E8: Transition | F8: FRONT SQUATS
E9: Active Rest / Recovery | F9: INCLINE BENCH
F10: FRONT PRESS
F11: CLEAN PRESS, BACK PRESS
F12: OHEAD SQUAT
F13: SQUAT TO BACK PRESS
F14: FRONT SQUAT TO PRESS
F15: CLEAN HI PULL
F16: SNATCH PULL

Sheet Athletes
A1: AthleteID | B1: Name | C1: Team | D1: Sex | E1: Class/Category | F1: Primary Event | G1: Secondary Event | H1: DOB | I1: Coach | J1: Baseline Throw (m) | K1: Baseline Squat (lbs) | L1: Baseline Bench (lbs) | M1: Baseline Clean (lbs) | N1: PB Throw (m) | O1: Status
A2: TRU001 | B2: Sample Athlete A | C2: UTech | D2: M | E2: Open | F2: Shot Put | G2: Discus | H2: 38061 | I2: M. Vassell | J2: 15.2 | K2: 180 | L2: 120 | M2: 100 | N2: 15.85 | O2: Active
A3: TRU002 | B3: Sample Athlete B | C3: Excelsior High | D3: F | E3: Class 1 | F3: Shot Put | G3: Discus | H3: 39996 | I3: M. Vassell | J3: 12.1 | K3: 90 | L3: 55 | M3: 60 | N3: 12.4 | O3: Active
A4: TRU003 | B4: Sample Athlete C | C4: Throwers R Us | D4: M | E4: U20 | F4: Javelin | H4: 39604 | I4: M. Vassell | J4: 54 | K4: 140 | L4: 95 | M4: 85 | N4: 57.2 | O4: Active

Sheet Annual Plan
A1: Season Start (Monday): | C1: 46272 | E1: Change this date and all 52 weeks re-date automatically.
A3: Week # | B3: Week Beginning | C3: Phase | D3: Primary Focus | E3: Throw Sessions | F3: Gym Sessions | G3: Intensity | H3: Volume | I3: Planned Meet | J3: Notes
A4: 1 | B4: =$C$1+(1-1)*7 -> 46272 | C4: General Preparation (GPP) | D4: General strength, work capacity, mobility, multi-throws with light implements, sprint & jump base | E4: 3 | F4: 4 | G4: Low-Mod | H4: High
A5: 2 | B5: =$C$1+(2-1)*7 -> 46279 | C5: General Preparation (GPP) | D5: General strength, work capacity, mobility, multi-throws with light implements, sprint & jump base | E5: 3 | F5: 4 | G5: Low-Mod | H5: High
A6: 3 | B6: =$C$1+(3-1)*7 -> 46286 | C6: General Preparation (GPP) | D6: General strength, work capacity, mobility, multi-throws with light implements, sprint & jump base | E6: 3 | F6: 4 | G6: Low-Mod | H6: High
A7: 4 | B7: =$C$1+(4-1)*7 -> 46293 | C7: General Preparation (GPP) | D7: General strength, work capacity, mobility, multi-throws with light implements, sprint & jump base | E7: 3 | F7: 4 | G7: Low-Mod | H7: High
A8: 5 | B8: =$C$1+(5-1)*7 -> 46300 | C8: General Preparation (GPP) | D8: General strength, work capacity, mobility, multi-throws with light implements, sprint & jump base | E8: 3 | F8: 4 | G8: Low-Mod | H8: High
A9: 6 | B9: =$C$1+(6-1)*7 -> 46307 | C9: General Preparation (GPP) | D9: General strength, work capacity, mobility, multi-throws with light implements, sprint & jump base | E9: 3 | F9: 4 | G9: Low-Mod | H9: High
A10: 7 | B10: =$C$1+(7-1)*7 -> 46314 | C10: General Preparation (GPP) | D10: General strength, work capacity, mobility, multi-throws with light implements, sprint & jump base | E10: 3 | F10: 4 | G10: Low-Mod | H10: High
A11: 8 | B11: =$C$1+(8-1)*7 -> 46321 | C11: General Preparation (GPP) | D11: General strength, work capacity, mobility, multi-throws with light implements, sprint & jump base | E11: 3 | F11: 4 | G11: Low-Mod | H11: High
A12: 9 | B12: =$C$1+(9-1)*7 -> 46328 | C12: Specific Preparation (SPP) | D12: Event technique volume, heavy strength block (squat/clean emphasis), heavy & standard implements | E12: 4 | F12: 4 | G12: Moderate | H12: High
A13: 10 | B13: =$C$1+(10-1)*7 -> 46335 | C13: Specific Preparation (SPP) | D13: Event technique volume, heavy strength block (squat/clean emphasis), heavy & standard implements | E13: 4 | F13: 4 | G13: Moderate | H13: High
A14: 11 | B14: =$C$1+(11-1)*7 -> 46342 | C14: Specific Preparation (SPP) | D14: Event technique volume, heavy strength block (squat/clean emphasis), heavy & standard implements | E14: 4 | F14: 4 | G14: Moderate | H14: High
A15: 12 | B15: =$C$1+(12-1)*7 -> 46349 | C15: Specific Preparation (SPP) | D15: Event technique volume, heavy strength block (squat/clean emphasis), heavy & standard implements | E15: 4 | F15: 4 | G15: Moderate | H15: High
A16: 13 | B16: =$C$1+(13-1)*7 -> 46356 | C16: Specific Preparation (SPP) | D16: Event technique volume, heavy strength block (squat/clean emphasis), heavy & standard implements | E16: 4 | F16: 4 | G16: Moderate | H16: High
A17: 14 | B17: =$C$1+(14-1)*7 -> 46363 | C17: Specific Preparation (SPP) | D17: Event technique volume, heavy strength block (squat/clean emphasis), heavy & standard implements | E17: 4 | F17: 4 | G17: Moderate | H17: High
A18: 15 | B18: =$C$1+(15-1)*7 -> 46370 | C18: Pre-Competition | D18: Technical refinement at full intensity, convert strength to power, standard implement, openers practice | E18: 4 | F18: 3 | G18: Mod-High | H18: Moderate
A19: 16 | B19: =$C$1+(16-1)*7 -> 46377 | C19: Pre-Competition | D19: Technical refinement at full intensity, convert strength to power, standard implement, openers practice | E19: 4 | F19: 3 | G19: Mod-High | H19: Moderate
A20: 17 | B20: =$C$1+(17-1)*7 -> 46384 | C20: Pre-Competition | D20: Technical refinement at full intensity, convert strength to power, standard implement, openers practice | E20: 4 | F20: 3 | G20: Mod-High | H20: Moderate
A21: 18 | B21: =$C$1+(18-1)*7 -> 46391 | C21: Pre-Competition | D21: Technical refinement at full intensity, convert strength to power, standard implement, openers practice | E21: 4 | F21: 3 | G21: Mod-High | H21: Moderate | I21: Ted Dwyer Invitational (early Jan)
A22: 19 | B22: =$C$1+(19-1)*7 -> 46398 | C22: Competition 1 | D22: Compete & sharpen: full-intensity throwing, maintenance strength, video review after each meet | E22: 3 | F22: 2 | G22: High | H22: Low-Mod
A23: 20 | B23: =$C$1+(20-1)*7 -> 46405 | C23: Competition 1 | D23: Compete & sharpen: full-intensity throwing, maintenance strength, video review after each meet | E23: 3 | F23: 2 | G23: High | H23: Low-Mod | I23: BIG SHOT INVITATIONAL
A24: 21 | B24: =$C$1+(21-1)*7 -> 46412 | C24: Competition 1 | D24: Compete & sharpen: full-intensity throwing, maintenance strength, video review after each meet | E24: 3 | F24: 2 | G24: High | H24: Low-Mod
A25: 22 | B25: =$C$1+(22-1)*7 -> 46419 | C25: Competition 1 | D25: Compete & sharpen: full-intensity throwing, maintenance strength, video review after each meet | E25: 3 | F25: 2 | G25: High | H25: Low-Mod
A26: 23 | B26: =$C$1+(23-1)*7 -> 46426 | C26: Competition 1 | D26: Compete & sharpen: full-intensity throwing, maintenance strength, video review after each meet | E26: 3 | F26: 2 | G26: High | H26: Low-Mod | I26: KING OF THE RING (Feb 14)
A27: 24 | B27: =$C$1+(24-1)*7 -> 46433 | C27: Competition 1 | D27: Compete & sharpen: full-intensity throwing, maintenance strength, video review after each meet | E27: 3 | F27: 2 | G27: High | H27: Low-Mod
A28: 25 | B28: =$C$1+(25-1)*7 -> 46440 | C28: Competition 1 | D28: Compete & sharpen: full-intensity throwing, maintenance strength, video review after each meet | E28: 3 | F28: 2 | G28: High | H28: Low-Mod
A29: 26 | B29: =$C$1+(26-1)*7 -> 46447 | C29: Competition 1 | D29: Compete & sharpen: full-intensity throwing, maintenance strength, video review after each meet | E29: 3 | F29: 2 | G29: High | H29: Low-Mod | I29: Development meet
A30: 27 | B30: =$C$1+(27-1)*7 -> 46454 | C30: Competition 1 | D30: Compete & sharpen: full-intensity throwing, maintenance strength, video review after each meet | E30: 3 | F30: 2 | G30: High | H30: Low-Mod
A31: 28 | B31: =$C$1+(28-1)*7 -> 46461 | C31: Competition 1 | D31: Compete & sharpen: full-intensity throwing, maintenance strength, video review after each meet | E31: 3 | F31: 2 | G31: High | H31: Low-Mod
A32: 29 | B32: =$C$1+(29-1)*7 -> 46468 | C32: Competition 1 | D32: Compete & sharpen: full-intensity throwing, maintenance strength, video review after each meet | E32: 3 | F32: 2 | G32: High | H32: Low-Mod
A33: 30 | B33: =$C$1+(30-1)*7 -> 46475 | C33: Competition 1 | D33: Compete & sharpen: full-intensity throwing, maintenance strength, video review after each meet | E33: 3 | F33: 2 | G33: High | H33: Low-Mod | I33: Boys & Girls Champs
A34: 31 | B34: =$C$1+(31-1)*7 -> 46482 | C34: Peak / Championships | D34: Taper: low volume, maximal intent, competition simulation, recovery priority (Champs / Carifta window) | E34: 2 | F34: 2 | G34: Very High | H34: Low
A35: 32 | B35: =$C$1+(32-1)*7 -> 46489 | C35: Peak / Championships | D35: Taper: low volume, maximal intent, competition simulation, recovery priority (Champs / Carifta window) | E35: 2 | F35: 2 | G35: Very High | H35: Low | I35: Carifta Trials
A36: 33 | B36: =$C$1+(33-1)*7 -> 46496 | C36: Peak / Championships | D36: Taper: low volume, maximal intent, competition simulation, recovery priority (Champs / Carifta window) | E36: 2 | F36: 2 | G36: Very High | H36: Low
A37: 34 | B37: =$C$1+(34-1)*7 -> 46503 | C37: Peak / Championships | D37: Taper: low volume, maximal intent, competition simulation, recovery priority (Champs / Carifta window) | E37: 2 | F37: 2 | G37: Very High | H37: Low | I37: Carifta Games
A38: 35 | B38: =$C$1+(35-1)*7 -> 46510 | C38: Competition 2 / Nationals | D38: Rebuild short strength block then re-peak for JAAA Nationals / senior season | E38: 3 | F38: 3 | G38: High | H38: Moderate
A39: 36 | B39: =$C$1+(36-1)*7 -> 46517 | C39: Competition 2 / Nationals | D39: Rebuild short strength block then re-peak for JAAA Nationals / senior season | E39: 3 | F39: 3 | G39: High | H39: Moderate
A40: 37 | B40: =$C$1+(37-1)*7 -> 46524 | C40: Competition 2 / Nationals | D40: Rebuild short strength block then re-peak for JAAA Nationals / senior season | E40: 3 | F40: 3 | G40: High | H40: Moderate
A41: 38 | B41: =$C$1+(38-1)*7 -> 46531 | C41: Competition 2 / Nationals | D41: Rebuild short strength block then re-peak for JAAA Nationals / senior season | E41: 3 | F41: 3 | G41: High | H41: Moderate | I41: Puma Series
...

Sheet Meet Schedule
A1: MeetID | B1: Date | C1: Meet Name | D1: Venue | E1: Entry Deadline | F1: Registration Link | G1: Status | H1: Notes
A2: M001 | B2: 46389 | C2: Ted Dwyer Invitational | D2: Excelsior High School | E2: 46386 | G2: Confirmed
A3: M002 | B3: 46410 | C3: Big Shot Invitational (19th) | D3: Excelsior High School | E3: 46407 | F3: https://fortistiming.co/meets/register/ | G3: Confirmed | H3: Throwers R Us flagship
A4: M003 | B4: 46431 | C4: King of the Ring (22nd) | D4: Excelsior High School | E4: 46428 | F4: https://fortistiming.co/meets/register/ | G4: Confirmed | H4: Valentine's weekend staging
A5: M004 | C5: Boys & Girls Champs | D5: National Stadium | G5: TBC | H5: Update when JAAA publishes
A6: M005 | C6: JAAA National Championships | D6: National Stadium | G6: TBC

Sheet Weekly Results
A1: EntryID | B1: Date | C1: Week # | D1: AthleteID | E1: Event | F1: Best Throw (m) | G1: Squat (lbs) | H1: Bench (lbs) | I1: Power Clean (lbs) | J1: RPE (1-10) | K1: Meet Result (Y/N) | L1: Meet Name | M1: Notes
A2: E0001 | B2: 46277 | C2: 1 | D2: TRU001 | E2: Shot Put | F2: 15.1 | G2: 180 | H2: 120 | I2: 100 | J2: 7 | K2: N | M2: Sample data - delete
A3: E0002 | B3: 46277 | C3: 1 | D3: TRU002 | E3: Shot Put | F3: 12.05 | G3: 90 | H3: 55 | I3: 60 | J3: 6 | K3: N | M3: Sample data - delete
A4: E0003 | B4: 46277 | C4: 1 | D4: TRU003 | E4: Javelin | F4: 54.2 | G4: 140 | H4: 95 | I4: 85 | J4: 7 | K4: N | M4: Sample data - delete
A5: E0004 | B5: 46284 | C5: 2 | D5: TRU001 | E5: Shot Put | F5: 15.32 | G5: 182.5 | H5: 120 | I5: 102.5 | J5: 8 | K5: N
A6: E0005 | B6: 46284 | C6: 2 | D6: TRU002 | E6: Shot Put | F6: 12.22 | G6: 92.5 | H6: 57.5 | I6: 62.5 | J6: 7 | K6: N
A7: E0006 | B7: 46284 | C7: 2 | D7: TRU003 | E7: Javelin | F7: 55.1 | G7: 142.5 | H7: 95 | I7: 87.5 | J7: 7 | K7: N
A8: E0007 | B8: 46291 | C8: 3 | D8: TRU001 | E8: Shot Put | F8: 15.05 | G8: 180 | H8: 122.5 | I8: 100 | J8: 9 | K8: N | M8: Heavy fatigue week
A9: E0008 | B9: 46291 | C9: 3 | D9: TRU002 | E9: Shot Put | F9: 12.3 | G9: 92.5 | H9: 57.5 | I9: 62.5 | J9: 7 | K9: N
A10: E0009 | B10: 46291 | C10: 3 | D10: TRU003 | E10: Javelin | F10: 53.8 | G10: 140 | H10: 97.5 | I10: 85 | J10: 8 | K10: N
A11: E0010 | B11: 46298 | C11: 4 | D11: TRU001 | E11: Shot Put | F11: 15.48 | G11: 185 | H11: 122.5 | I11: 105 | J11: 8 | K11: Y | L11: Development meet
A12: E0011 | B12: 46298 | C12: 4 | D12: TRU002 | E12: Shot Put | F12: 12.18 | G12: 95 | H12: 60 | I12: 65 | J12: 8 | K12: N
A13: E0012 | B13: 46298 | C13: 4 | D13: TRU003 | E13: Javelin | F13: 56.02 | G13: 145 | H13: 100 | I13: 90 | J13: 8 | K13: Y | L13: Development meet

Sheet Athlete Report
A1: WEEKLY ATHLETE REPORT
A3: Select Athlete ID: | B3: TRU001
A4: Name: | B4: =IFERROR(INDEX(Athletes!$B$2:$B$40,MATCH($B$3,Athletes!$A$2:$A$40,0)),"") -> Sample Athlete A
A5: Team: | B5: =IFERROR(INDEX(Athletes!$C$2:$C$40,MATCH($B$3,Athletes!$A$2:$A$40,0)),"") -> UTech
A6: Primary Event: | B6: =IFERROR(INDEX(Athletes!$F$2:$F$40,MATCH($B$3,Athletes!$A$2:$A$40,0)),"") -> Shot Put
A7: Latest Training Week: | B7: =IF(COUNTIF('Weekly Results'!$D$2:$D$2000,$B$3)=0,"",_xlfn.MAXIFS('Weekly Results'!$C$2:$C$2000,'Weekly Results'!$D$2:$D$2000,$B$3)) -> 4
A9: Metric | B9: This Week | C9: Last Week | D9: Change | E9: % Change | F9: Trend | G9: Baseline | H9: Season Best | I9: vs Baseline %
A10: Best Throw (m) | B10: =IF($B$7="","",IF(_xlfn.MAXIFS('Weekly Results'!$F$2:$F$2000,'Weekly Results'!$D$2:$D$2000,$B$3,'Weekly Results'!$C$2:$C$2000,$B$7)=0,"",_xlfn.MAXIFS('Weekly Results'!$F$2:$F$2000,'Weekly Results'!$D$2:$D$2000,$B$3,'Weekly Results'!$C$2:$C$2000,$B$7))) -> 15.48 | C10: =IF($B$7="","",IF(_xlfn.MAXIFS('Weekly Results'!$F$2:$F$2000,'Weekly Results'!$D$2:$D$2000,$B$3,'Weekly Results'!$C$2:$C$2000,$B$7-1)=0,"",_xlfn.MAXIFS('Weekly Results'!$F$2:$F$2000,'Weekly Results'!$D$2:$D$2000,$B$3,'Weekly Results'!$C$2:$C$2000,$B$7-1))) -> 15.05 | D10: =IF(OR(B10="",C10=""),"",B10-C10) -> 0.43 | E10: =IF(OR(B10="",C10="",C10=0),"",(B10-C10)/C10) -> 0.028571429 | F10: =IF(OR(B10="",C10=""),"",IF(B10>C10,"▲",IF(B10<C10,"▼","—"))) -> ▲ | G10: =IFERROR(INDEX(Athletes!$J$2:$J$40,MATCH($B$3,Athletes!$A$2:$A$40,0)),"") -> 15.2 | H10: =IF(COUNTIF('Weekly Results'!$D$2:$D$2000,$B$3)=0,"",IF(_xlfn.MAXIFS('Weekly Results'!$F$2:$F$2000,'Weekly Results'!$D$2:$D$2000,$B$3)=0,"",_xlfn.MAXIFS('Weekly Results'!$F$2:$F$2000,'Weekly Results'!$D$2:$D$2000,$B$3))) -> 15.48 | I10: =IF(OR(G10="",H10="",G10=0),"",(H10-G10)/G10) -> 0.018421053
A11: Squat (lbs) | B11: =IF($B$7="","",IF(_xlfn.MAXIFS('Weekly Results'!$G$2:$G$2000,'Weekly Results'!$D$2:$D$2000,$B$3,'Weekly Results'!$C$2:$C$2000,$B$7)=0,"",_xlfn.MAXIFS('Weekly Results'!$G$2:$G$2000,'Weekly Results'!$D$2:$D$2000,$B$3,'Weekly Results'!$C$2:$C$2000,$B$7))) -> 185 | C11: =IF($B$7="","",IF(_xlfn.MAXIFS('Weekly Results'!$G$2:$G$2000,'Weekly Results'!$D$2:$D$2000,$B$3,'Weekly Results'!$C$2:$C$2000,$B$7-1)=0,"",_xlfn.MAXIFS('Weekly Results'!$G$2:$G$2000,'Weekly Results'!$D$2:$D$2000,$B$3,'Weekly Results'!$C$2:$C$2000,$B$7-1))) -> 180 | D11: =IF(OR(B11="",C11=""),"",B11-C11) -> 5 | E11: =IF(OR(B11="",C11="",C11=0),"",(B11-C11)/C11) -> 0.027777778 | F11: =IF(OR(B11="",C11=""),"",IF(B11>C11,"▲",IF(B11<C11,"▼","—"))) -> ▲ | G11: =IFERROR(INDEX(Athletes!$K$2:$K$40,MATCH($B$3,Athletes!$A$2:$A$40,0)),"") -> 180 | H11: =IF(COUNTIF('Weekly Results'!$D$2:$D$2000,$B$3)=0,"",IF(_xlfn.MAXIFS('Weekly Results'!$G$2:$G$2000,'Weekly Results'!$D$2:$D$2000,$B$3)=0,"",_xlfn.MAXIFS('Weekly Results'!$G$2:$G$2000,'Weekly Results'!$D$2:$D$2000,$B$3))) -> 185 | I11: =IF(OR(G11="",H11="",G11=0),"",(H11-G11)/G11) -> 0.027777778
A12: Bench (lbs) | B12: =IF($B$7="","",IF(_xlfn.MAXIFS('Weekly Results'!$H$2:$H$2000,'Weekly Results'!$D$2:$D$2000,$B$3,'Weekly Results'!$C$2:$C$2000,$B$7)=0,"",_xlfn.MAXIFS('Weekly Results'!$H$2:$H$2000,'Weekly Results'!$D$2:$D$2000,$B$3,'Weekly Results'!$C$2:$C$2000,$B$7))) -> 122.5 | C12: =IF($B$7="","",IF(_xlfn.MAXIFS('Weekly Results'!$H$2:$H$2000,'Weekly Results'!$D$2:$D$2000,$B$3,'Weekly Results'!$C$2:$C$2000,$B$7-1)=0,"",_xlfn.MAXIFS('Weekly Results'!$H$2:$H$2000,'Weekly Results'!$D$2:$D$2000,$B$3,'Weekly Results'!$C$2:$C$2000,$B$7-1))) -> 122.5 | D12: =IF(OR(B12="",C12=""),"",B12-C12) -> 0 | E12: =IF(OR(B12="",C12="",C12=0),"",(B12-C12)/C12) -> 0 | F12: =IF(OR(B12="",C12=""),"",IF(B12>C12,"▲",IF(B12<C12,"▼","—"))) -> — | G12: =IFERROR(INDEX(Athletes!$L$2:$L$40,MATCH($B$3,Athletes!$A$2:$A$40,0)),"") -> 120 | H12: =IF(COUNTIF('Weekly Results'!$D$2:$D$2000,$B$3)=0,"",IF(_xlfn.MAXIFS('Weekly Results'!$H$2:$H$2000,'Weekly Results'!$D$2:$D$2000,$B$3)=0,"",_xlfn.MAXIFS('Weekly Results'!$H$2:$H$2000,'Weekly Results'!$D$2:$D$2000,$B$3))) -> 122.5 | I12: =IF(OR(G12="",H12="",G12=0),"",(H12-G12)/G12) -> 0.020833333
A13: Power Clean (lbs) | B13: =IF($B$7="","",IF(_xlfn.MAXIFS('Weekly Results'!$I$2:$I$2000,'Weekly Results'!$D$2:$D$2000,$B$3,'Weekly Results'!$C$2:$C$2000,$B$7)=0,"",_xlfn.MAXIFS('Weekly Results'!$I$2:$I$2000,'Weekly Results'!$D$2:$D$2000,$B$3,'Weekly Results'!$C$2:$C$2000,$B$7))) -> 105 | C13: =IF($B$7="","",IF(_xlfn.MAXIFS('Weekly Results'!$I$2:$I$2000,'Weekly Results'!$D$2:$D$2000,$B$3,'Weekly Results'!$C$2:$C$2000,$B$7-1)=0,"",_xlfn.MAXIFS('Weekly Results'!$I$2:$I$2000,'Weekly Results'!$D$2:$D$2000,$B$3,'Weekly Results'!$C$2:$C$2000,$B$7-1))) -> 100 | D13: =IF(OR(B13="",C13=""),"",B13-C13) -> 5 | E13: =IF(OR(B13="",C13="",C13=0),"",(B13-C13)/C13) -> 0.05 | F13: =IF(OR(B13="",C13=""),"",IF(B13>C13,"▲",IF(B13<C13,"▼","—"))) -> ▲ | G13: =IFERROR(INDEX(Athletes!$M$2:$M$40,MATCH($B$3,Athletes!$A$2:$A$40,0)),"") -> 100 | H13: =IF(COUNTIF('Weekly Results'!$D$2:$D$2000,$B$3)=0,"",IF(_xlfn.MAXIFS('Weekly Results'!$I$2:$I$2000,'Weekly Results'!$D$2:$D$2000,$B$3)=0,"",_xlfn.MAXIFS('Weekly Results'!$I$2:$I$2000,'Weekly Results'!$D$2:$D$2000,$B$3))) -> 105 | I13: =IF(OR(G13="",H13="",G13=0),"",(H13-G13)/G13) -> 0.05
A16: 16-WEEK TREND (best of each training week)
A17: Week # | B17: Best Throw (m) | C17: Squat (lbs) | D17: Bench (lbs) | E17: Power Clean (lbs)
A18: 1 | B18: =IF($B$3="","",IF(_xlfn.MAXIFS('Weekly Results'!$F$2:$F$2000,'Weekly Results'!$D$2:$D$2000,$B$3,'Weekly Results'!$C$2:$C$2000,1)=0,"",_xlfn.MAXIFS('Weekly Results'!$F$2:$F$2000,'Weekly Results'!$D$2:$D$2000,$B$3,'Weekly Results'!$C$2:$C$2000,1))) -> 15.1 | C18: =IF($B$3="","",IF(_xlfn.MAXIFS('Weekly Results'!$G$2:$G$2000,'Weekly Results'!$D$2:$D$2000,$B$3,'Weekly Results'!$C$2:$C$2000,1)=0,"",_xlfn.MAXIFS('Weekly Results'!$G$2:$G$2000,'Weekly Results'!$D$2:$D$2000,$B$3,'Weekly Results'!$C$2:$C$2000,1))) -> 180 | D18: =IF($B$3="","",IF(_xlfn.MAXIFS('Weekly Results'!$H$2:$H$2000,'Weekly Results'!$D$2:$D$2000,$B$3,'Weekly Results'!$C$2:$C$2000,1)=0,"",_xlfn.MAXIFS('Weekly Results'!$H$2:$H$2000,'Weekly Results'!$D$2:$D$2000,$B$3,'Weekly Results'!$C$2:$C$2000,1))) -> 120 | E18: =IF($B$3="","",IF(_xlfn.MAXIFS('Weekly Results'!$I$2:$I$2000,'Weekly Results'!$D$2:$D$2000,$B$3,'Weekly Results'!$C$2:$C$2000,1)=0,"",_xlfn.MAXIFS('Weekly Results'!$I$2:$I$2000,'Weekly Results'!$D$2:$D$2000,$B$3,'Weekly Results'!$C$2:$C$2000,1))) -> 100
A19: 2 | B19: =IF($B$3="","",IF(_xlfn.MAXIFS('Weekly Results'!$F$2:$F$2000,'Weekly Results'!$D$2:$D$2000,$B$3,'Weekly Results'!$C$2:$C$2000,2)=0,"",_xlfn.MAXIFS('Weekly Results'!$F$2:$F$2000,'Weekly Results'!$D$2:$D$2000,$B$3,'Weekly Results'!$C$2:$C$2000,2))) -> 15.32 | C19: =IF($B$3="","",IF(_xlfn.MAXIFS('Weekly Results'!$G$2:$G$2000,'Weekly Results'!$D$2:$D$2000,$B$3,'Weekly Results'!$C$2:$C$2000,2)=0,"",_xlfn.MAXIFS('Weekly Results'!$G$2:$G$2000,'Weekly Results'!$D$2:$D$2000,$B$3,'Weekly Results'!$C$2:$C$2000,2))) -> 182.5 | D19: =IF($B$3="","",IF(_xlfn.MAXIFS('Weekly Results'!$H$2:$H$2000,'Weekly Results'!$D$2:$D$2000,$B$3,'Weekly Results'!$C$2:$C$2000,2)=0,"",_xlfn.MAXIFS('Weekly Results'!$H$2:$H$2000,'Weekly Results'!$D$2:$D$2000,$B$3,'Weekly Results'!$C$2:$C$2000,2))) -> 120 | E19: =IF($B$3="","",IF(_xlfn.MAXIFS('Weekly Results'!$I$2:$I$2000,'Weekly Results'!$D$2:$D$2000,$B$3,'Weekly Results'!$C$2:$C$2000,2)=0,"",_xlfn.MAXIFS('Weekly Results'!$I$2:$I$2000,'Weekly Results'!$D$2:$D$2000,$B$3,'Weekly Results'!$C$2:$C$2000,2))) -> 102.5
A20: 3 | B20: =IF($B$3="","",IF(_xlfn.MAXIFS('Weekly Results'!$F$2:$F$2000,'Weekly Results'!$D$2:$D$2000,$B$3,'Weekly Results'!$C$2:$C$2000,3)=0,"",_xlfn.MAXIFS('Weekly Results'!$F$2:$F$2000,'Weekly Results'!$D$2:$D$2000,$B$3,'Weekly Results'!$C$2:$C$2000,3))) -> 15.05 | C20: =IF($B$3="","",IF(_xlfn.MAXIFS('Weekly Results'!$G$2:$G$2000,'Weekly Results'!$D$2:$D$2000,$B$3,'Weekly Results'!$C$2:$C$2000,3)=0,"",_xlfn.MAXIFS('Weekly Results'!$G$2:$G$2000,'Weekly Results'!$D$2:$D$2000,$B$3,'Weekly Results'!$C$2:$C$2000,3))) -> 180 | D20: =IF($B$3="","",IF(_xlfn.MAXIFS('Weekly Results'!$H$2:$H$2000,'Weekly Results'!$D$2:$D$2000,$B$3,'Weekly Results'!$C$2:$C$2000,3)=0,"",_xlfn.MAXIFS('Weekly Results'!$H$2:$H$2000,'Weekly Results'!$D$2:$D$2000,$B$3,'Weekly Results'!$C$2:$C$2000,3))) -> 122.5 | E20: =IF($B$3="","",IF(_xlfn.MAXIFS('Weekly Results'!$I$2:$I$2000,'Weekly Results'!$D$2:$D$2000,$B$3,'Weekly Results'!$C$2:$C$2000,3)=0,"",_xlfn.MAXIFS('Weekly Results'!$I$2:$I$2000,'Weekly Results'!$D$2:$D$2000,$B$3,'Weekly Results'!$C$2:$C$2000,3))) -> 100
A21: 4 | B21: =IF($B$3="","",IF(_xlfn.MAXIFS('Weekly Results'!$F$2:$F$2000,'Weekly Results'!$D$2:$D$2000,$B$3,'Weekly Results'!$C$2:$C$2000,4)=0,"",_xlfn.MAXIFS('Weekly Results'!$F$2:$F$2000,'Weekly Results'!$D$2:$D$2000,$B$3,'Weekly Results'!$C$2:$C$2000,4))) -> 15.48 | C21: =IF($B$3="","",IF(_xlfn.MAXIFS('Weekly Results'!$G$2:$G$2000,'Weekly Results'!$D$2:$D$2000,$B$3,'Weekly Results'!$C$2:$C$2000,4)=0,"",_xlfn.MAXIFS('Weekly Results'!$G$2:$G$2000,'Weekly Results'!$D$2:$D$2000,$B$3,'Weekly Results'!$C$2:$C$2000,4))) -> 185 | D21: =IF($B$3="","",IF(_xlfn.MAXIFS('Weekly Results'!$H$2:$H$2000,'Weekly Results'!$D$2:$D$2000,$B$3,'Weekly Results'!$C$2:$C$2000,4)=0,"",_xlfn.MAXIFS('Weekly Results'!$H$2:$H$2000,'Weekly Results'!$D$2:$D$2000,$B$3,'Weekly Results'!$C$2:$C$2000,4))) -> 122.5 | E21: =IF($B$3="","",IF(_xlfn.MAXIFS('Weekly Results'!$I$2:$I$2000,'Weekly Results'!$D$2:$D$2000,$B$3,'Weekly Results'!$C$2:$C$2000,4)=0,"",_xlfn.MAXIFS('Weekly Results'!$I$2:$I$2000,'Weekly Results'!$D$2:$D$2000,$B$3,'Weekly Results'!$C$2:$C$2000,4))) -> 105
A22: 5 | B22: =IF($B$3="","",IF(_xlfn.MAXIFS('Weekly Results'!$F$2:$F$2000,'Weekly Results'!$D$2:$D$2000,$B$3,'Weekly Results'!$C$2:$C$2000,5)=0,"",_xlfn.MAXIFS('Weekly Results'!$F$2:$F$2000,'Weekly Results'!$D$2:$D$2000,$B$3,'Weekly Results'!$C$2:$C$2000,5))) | C22: =IF($B$3="","",IF(_xlfn.MAXIFS('Weekly Results'!$G$2:$G$2000,'Weekly Results'!$D$2:$D$2000,$B$3,'Weekly Results'!$C$2:$C$2000,5)=0,"",_xlfn.MAXIFS('Weekly Results'!$G$2:$G$2000,'Weekly Results'!$D$2:$D$2000,$B$3,'Weekly Results'!$C$2:$C$2000,5))) | D22: =IF($B$3="","",IF(_xlfn.MAXIFS('Weekly Results'!$H$2:$H$2000,'Weekly Results'!$D$2:$D$2000,$B$3,'Weekly Results'!$C$2:$C$2000,5)=0,"",_xlfn.MAXIFS('Weekly Results'!$H$2:$H$2000,'Weekly Results'!$D$2:$D$2000,$B$3,'Weekly Results'!$C$2:$C$2000,5))) | E22: =IF($B$3="","",IF(_xlfn.MAXIFS('Weekly Results'!$I$2:$I$2000,'Weekly Results'!$D$2:$D$2000,$B$3,'Weekly Results'!$C$2:$C$2000,5)=0,"",_xlfn.MAXIFS('Weekly Results'!$I$2:$I$2000,'Weekly Results'!$D$2:$D$2000,$B$3,'Weekly Results'!$C$2:$C$2000,5)))
A23: 6 | B23: =IF($B$3="","",IF(_xlfn.MAXIFS('Weekly Results'!$F$2:$F$2000,'Weekly Results'!$D$2:$D$2000,$B$3,'Weekly Results'!$C$2:$C$2000,6)=0,"",_xlfn.MAXIFS('Weekly Results'!$F$2:$F$2000,'Weekly Results'!$D$2:$D$2000,$B$3,'Weekly Results'!$C$2:$C$2000,6))) | C23: =IF($B$3="","",IF(_xlfn.MAXIFS('Weekly Results'!$G$2:$G$2000,'Weekly Results'!$D$2:$D$2000,$B$3,'Weekly Results'!$C$2:$C$2000,6)=0,"",_xlfn.MAXIFS('Weekly Results'!$G$2:$G$2000,'Weekly Results'!$D$2:$D$2000,$B$3,'Weekly Results'!$C$2:$C$2000,6))) | D23: =IF($B$3="","",IF(_xlfn.MAXIFS('Weekly Results'!$H$2:$H$2000,'Weekly Results'!$D$2:$D$2000,$B$3,'Weekly Results'!$C$2:$C$2000,6)=0,"",_xlfn.MAXIFS('Weekly Results'!$H$2:$H$2000,'Weekly Results'!$D$2:$D$2000,$B$3,'Weekly Results'!$C$2:$C$2000,6))) | E23: =IF($B$3="","",IF(_xlfn.MAXIFS('Weekly Results'!$I$2:$I$2000,'Weekly Results'!$D$2:$D$2000,$B$3,'Weekly Results'!$C$2:$C$2000,6)=0,"",_xlfn.MAXIFS('Weekly Results'!$I$2:$I$2000,'Weekly Results'!$D$2:$D$2000,$B$3,'Weekly Results'!$C$2:$C$2000,6)))
A24: 7 | B24: =IF($B$3="","",IF(_xlfn.MAXIFS('Weekly Results'!$F$2:$F$2000,'Weekly Results'!$D$2:$D$2000,$B$3,'Weekly Results'!$C$2:$C$2000,7)=0,"",_xlfn.MAXIFS('Weekly Results'!$F$2:$F$2000,'Weekly Results'!$D$2:$D$2000,$B$3,'Weekly Results'!$C$2:$C$2000,7))) | C24: =IF($B$3="","",IF(_xlfn.MAXIFS('Weekly Results'!$G$2:$G$2000,'Weekly Results'!$D$2:$D$2000,$B$3,'Weekly Results'!$C$2:$C$2000,7)=0,"",_xlfn.MAXIFS('Weekly Results'!$G$2:$G$2000,'Weekly Results'!$D$2:$D$2000,$B$3,'Weekly Results'!$C$2:$C$2000,7))) | D24: =IF($B$3="","",IF(_xlfn.MAXIFS('Weekly Results'!$H$2:$H$2000,'Weekly Results'!$D$2:$D$2000,$B$3,'Weekly Results'!$C$2:$C$2000,7)=0,"",_xlfn.MAXIFS('Weekly Results'!$H$2:$H$2000,'Weekly Results'!$D$2:$D$2000,$B$3,'Weekly Results'!$C$2:$C$2000,7))) | E24: =IF($B$3="","",IF(_xlfn.MAXIFS('Weekly Results'!$I$2:$I$2000,'Weekly Results'!$D$2:$D$2000,$B$3,'Weekly Results'!$C$2:$C$2000,7)=0,"",_xlfn.MAXIFS('Weekly Results'!$I$2:$I$2000,'Weekly Results'!$D$2:$D$2000,$B$3,'Weekly Results'!$C$2:$C$2000,7)))
A25: 8 | B25: =IF($B$3="","",IF(_xlfn.MAXIFS('Weekly Results'!$F$2:$F$2000,'Weekly Results'!$D$2:$D$2000,$B$3,'Weekly Results'!$C$2:$C$2000,8)=0,"",_xlfn.MAXIFS('Weekly Results'!$F$2:$F$2000,'Weekly Results'!$D$2:$D$2000,$B$3,'Weekly Results'!$C$2:$C$2000,8))) | C25: =IF($B$3="","",IF(_xlfn.MAXIFS('Weekly Results'!$G$2:$G$2000,'Weekly Results'!$D$2:$D$2000,$B$3,'Weekly Results'!$C$2:$C$2000,8)=0,"",_xlfn.MAXIFS('Weekly Results'!$G$2:$G$2000,'Weekly Results'!$D$2:$D$2000,$B$3,'Weekly Results'!$C$2:$C$2000,8))) | D25: =IF($B$3="","",IF(_xlfn.MAXIFS('Weekly Results'!$H$2:$H$2000,'Weekly Results'!$D$2:$D$2000,$B$3,'Weekly Results'!$C$2:$C$2000,8)=0,"",_xlfn.MAXIFS('Weekly Results'!$H$2:$H$2000,'Weekly Results'!$D$2:$D$2000,$B$3,'Weekly Results'!$C$2:$C$2000,8))) | E25: =IF($B$3="","",IF(_xlfn.MAXIFS('Weekly Results'!$I$2:$I$2000,'Weekly Results'!$D$2:$D$2000,$B$3,'Weekly Results'!$C$2:$C$2000,8)=0,"",_xlfn.MAXIFS('Weekly Results'!$I$2:$I$2000,'Weekly Results'!$D$2:$D$2000,$B$3,'Weekly Results'!$C$2:$C$2000,8)))
A26: 9 | B26: =IF($B$3="","",IF(_xlfn.MAXIFS('Weekly Results'!$F$2:$F$2000,'Weekly Results'!$D$2:$D$2000,$B$3,'Weekly Results'!$C$2:$C$2000,9)=0,"",_xlfn.MAXIFS('Weekly Results'!$F$2:$F$2000,'Weekly Results'!$D$2:$D$2000,$B$3,'Weekly Results'!$C$2:$C$2000,9))) | C26: =IF($B$3="","",IF(_xlfn.MAXIFS('Weekly Results'!$G$2:$G$2000,'Weekly Results'!$D$2:$D$2000,$B$3,'Weekly Results'!$C$2:$C$2000,9)=0,"",_xlfn.MAXIFS('Weekly Results'!$G$2:$G$2000,'Weekly Results'!$D$2:$D$2000,$B$3,'Weekly Results'!$C$2:$C$2000,9))) | D26: =IF($B$3="","",IF(_xlfn.MAXIFS('Weekly Results'!$H$2:$H$2000,'Weekly Results'!$D$2:$D$2000,$B$3,'Weekly Results'!$C$2:$C$2000,9)=0,"",_xlfn.MAXIFS('Weekly Results'!$H$2:$H$2000,'Weekly Results'!$D$2:$D$2000,$B$3,'Weekly Results'!$C$2:$C$2000,9))) | E26: =IF($B$3="","",IF(_xlfn.MAXIFS('Weekly Results'!$I$2:$I$2000,'Weekly Results'!$D$2:$D$2000,$B$3,'Weekly Results'!$C$2:$C$2000,9)=0,"",_xlfn.MAXIFS('Weekly Results'!$I$2:$I$2000,'Weekly Results'!$D$2:$D$2000,$B$3,'Weekly Results'!$C$2:$C$2000,9)))
A27: 10 | B27: =IF($B$3="","",IF(_xlfn.MAXIFS('Weekly Results'!$F$2:$F$2000,'Weekly Results'!$D$2:$D$2000,$B$3,'Weekly Results'!$C$2:$C$2000,10)=0,"",_xlfn.MAXIFS('Weekly Results'!$F$2:$F$2000,'Weekly Results'!$D$2:$D$2000,$B$3,'Weekly Results'!$C$2:$C$2000,10))) | C27: =IF($B$3="","",IF(_xlfn.MAXIFS('Weekly Results'!$G$2:$G$2000,'Weekly Results'!$D$2:$D$2000,$B$3,'Weekly Results'!$C$2:$C$2000,10)=0,"",_xlfn.MAXIFS('Weekly Results'!$G$2:$G$2000,'Weekly Results'!$D$2:$D$2000,$B$3,'Weekly Results'!$C$2:$C$2000,10))) | D27: =IF($B$3="","",IF(_xlfn.MAXIFS('Weekly Results'!$H$2:$H$2000,'Weekly Results'!$D$2:$D$2000,$B$3,'Weekly Results'!$C$2:$C$2000,10)=0,"",_xlfn.MAXIFS('Weekly Results'!$H$2:$H$2000,'Weekly Results'!$D$2:$D$2000,$B$3,'Weekly Results'!$C$2:$C$2000,10))) | E27: =IF($B$3="","",IF(_xlfn.MAXIFS('Weekly Results'!$I$2:$I$2000,'Weekly Results'!$D$2:$D$2000,$B$3,'Weekly Results'!$C$2:$C$2000,10)=0,"",_xlfn.MAXIFS('Weekly Results'!$I$2:$I$2000,'Weekly Results'!$D$2:$D$2000,$B$3,'Weekly Results'!$C$2:$C$2000,10)))
A28: 11 | B28: =IF($B$3="","",IF(_xlfn.MAXIFS('Weekly Results'!$F$2:$F$2000,'Weekly Results'!$D$2:$D$2000,$B$3,'Weekly Results'!$C$2:$C$2000,11)=0,"",_xlfn.MAXIFS('Weekly Results'!$F$2:$F$2000,'Weekly Results'!$D$2:$D$2000,$B$3,'Weekly Results'!$C$2:$C$2000,11))) | C28: =IF($B$3="","",IF(_xlfn.MAXIFS('Weekly Results'!$G$2:$G$2000,'Weekly Results'!$D$2:$D$2000,$B$3,'Weekly Results'!$C$2:$C$2000,11)=0,"",_xlfn.MAXIFS('Weekly Results'!$G$2:$G$2000,'Weekly Results'!$D$2:$D$2000,$B$3,'Weekly Results'!$C$2:$C$2000,11))) | D28: =IF($B$3="","",IF(_xlfn.MAXIFS('Weekly Results'!$H$2:$H$2000,'Weekly Results'!$D$2:$D$2000,$B$3,'Weekly Results'!$C$2:$C$2000,11)=0,"",_xlfn.MAXIFS('Weekly Results'!$H$2:$H$2000,'Weekly Results'!$D$2:$D$2000,$B$3,'Weekly Results'!$C$2:$C$2000,11))) | E28: =IF($B$3="","",IF(_xlfn.MAXIFS('Weekly Results'!$I$2:$I$2000,'Weekly Results'!$D$2:$D$2000,$B$3,'Weekly Results'!$C$2:$C$2000,11)=0,"",_xlfn.MAXIFS('Weekly Results'!$I$2:$I$2000,'Weekly Results'!$D$2:$D$2000,$B$3,'Weekly Results'!$C$2:$C$2000,11)))
A29: 12 | B29: =IF($B$3="","",IF(_xlfn.MAXIFS('Weekly Results'!$F$2:$F$2000,'Weekly Results'!$D$2:$D$2000,$B$3,'Weekly Results'!$C$2:$C$2000,12)=0,"",_xlfn.MAXIFS('Weekly Results'!$F$2:$F$2000,'Weekly Results'!$D$2:$D$2000,$B$3,'Weekly Results'!$C$2:$C$2000,12))) | C29: =IF($B$3="","",IF(_xlfn.MAXIFS('Weekly Results'!$G$2:$G$2000,'Weekly Results'!$D$2:$D$2000,$B$3,'Weekly Results'!$C$2:$C$2000,12)=0,"",_xlfn.MAXIFS('Weekly Results'!$G$2:$G$2000,'Weekly Results'!$D$2:$D$2000,$B$3,'Weekly Results'!$C$2:$C$2000,12))) | D29: =IF($B$3="","",IF(_xlfn.MAXIFS('Weekly Results'!$H$2:$H$2000,'Weekly Results'!$D$2:$D$2000,$B$3,'Weekly Results'!$C$2:$C$2000,12)=0,"",_xlfn.MAXIFS('Weekly Results'!$H$2:$H$2000,'Weekly Results'!$D$2:$D$2000,$B$3,'Weekly Results'!$C$2:$C$2000,12))) | E29: =IF($B$3="","",IF(_xlfn.MAXIFS('Weekly Results'!$I$2:$I$2000,'Weekly Results'!$D$2:$D$2000,$B$3,'Weekly Results'!$C$2:$C$2000,12)=0,"",_xlfn.MAXIFS('Weekly Results'!$I$2:$I$2000,'Weekly Results'!$D$2:$D$2000,$B$3,'Weekly Results'!$C$2:$C$2000,12)))
A30: 13 | B30: =IF($B$3="","",IF(_xlfn.MAXIFS('Weekly Results'!$F$2:$F$2000,'Weekly Results'!$D$2:$D$2000,$B$3,'Weekly Results'!$C$2:$C$2000,13)=0,"",_xlfn.MAXIFS('Weekly Results'!$F$2:$F$2000,'Weekly Results'!$D$2:$D$2000,$B$3,'Weekly Results'!$C$2:$C$2000,13))) | C30: =IF($B$3="","",IF(_xlfn.MAXIFS('Weekly Results'!$G$2:$G$2000,'Weekly Results'!$D$2:$D$2000,$B$3,'Weekly Results'!$C$2:$C$2000,13)=0,"",_xlfn.MAXIFS('Weekly Results'!$G$2:$G$2000,'Weekly Results'!$D$2:$D$2000,$B$3,'Weekly Results'!$C$2:$C$2000,13))) | D30: =IF($B$3="","",IF(_xlfn.MAXIFS('Weekly Results'!$H$2:$H$2000,'Weekly Results'!$D$2:$D$2000,$B$3,'Weekly Results'!$C$2:$C$2000,13)=0,"",_xlfn.MAXIFS('Weekly Results'!$H$2:$H$2000,'Weekly Results'!$D$2:$D$2000,$B$3,'Weekly Results'!$C$2:$C$2000,13))) | E30: =IF($B$3="","",IF(_xlfn.MAXIFS('Weekly Results'!$I$2:$I$2000,'Weekly Results'!$D$2:$D$2000,$B$3,'Weekly Results'!$C$2:$C$2000,13)=0,"",_xlfn.MAXIFS('Weekly Results'!$I$2:$I$2000,'Weekly Results'!$D$2:$D$2000,$B$3,'Weekly Results'!$C$2:$C$2000,13)))
A31: 14 | B31: =IF($B$3="","",IF(_xlfn.MAXIFS('Weekly Results'!$F$2:$F$2000,'Weekly Results'!$D$2:$D$2000,$B$3,'Weekly Results'!$C$2:$C$2000,14)=0,"",_xlfn.MAXIFS('Weekly Results'!$F$2:$F$2000,'Weekly Results'!$D$2:$D$2000,$B$3,'Weekly Results'!$C$2:$C$2000,14))) | C31: =IF($B$3="","",IF(_xlfn.MAXIFS('Weekly Results'!$G$2:$G$2000,'Weekly Results'!$D$2:$D$2000,$B$3,'Weekly Results'!$C$2:$C$2000,14)=0,"",_xlfn.MAXIFS('Weekly Results'!$G$2:$G$2000,'Weekly Results'!$D$2:$D$2000,$B$3,'Weekly Results'!$C$2:$C$2000,14))) | D31: =IF($B$3="","",IF(_xlfn.MAXIFS('Weekly Results'!$H$2:$H$2000,'Weekly Results'!$D$2:$D$2000,$B$3,'Weekly Results'!$C$2:$C$2000,14)=0,"",_xlfn.MAXIFS('Weekly Results'!$H$2:$H$2000,'Weekly Results'!$D$2:$D$2000,$B$3,'Weekly Results'!$C$2:$C$2000,14))) | E31: =IF($B$3="","",IF(_xlfn.MAXIFS('Weekly Results'!$I$2:$I$2000,'Weekly Results'!$D$2:$D$2000,$B$3,'Weekly Results'!$C$2:$C$2000,14)=0,"",_xlfn.MAXIFS('Weekly Results'!$I$2:$I$2000,'Weekly Results'!$D$2:$D$2000,$B$3,'Weekly Results'!$C$2:$C$2000,14)))
A32: 15 | B32: =IF($B$3="","",IF(_xlfn.MAXIFS('Weekly Results'!$F$2:$F$2000,'Weekly Results'!$D$2:$D$2000,$B$3,'Weekly Results'!$C$2:$C$2000,15)=0,"",_xlfn.MAXIFS('Weekly Results'!$F$2:$F$2000,'Weekly Results'!$D$2:$D$2000,$B$3,'Weekly Results'!$C$2:$C$2000,15))) | C32: =IF($B$3="","",IF(_xlfn.MAXIFS('Weekly Results'!$G$2:$G$2000,'Weekly Results'!$D$2:$D$2000,$B$3,'Weekly Results'!$C$2:$C$2000,15)=0,"",_xlfn.MAXIFS('Weekly Results'!$G$2:$G$2000,'Weekly Results'!$D$2:$D$2000,$B$3,'Weekly Results'!$C$2:$C$2000,15))) | D32: =IF($B$3="","",IF(_xlfn.MAXIFS('Weekly Results'!$H$2:$H$2000,'Weekly Results'!$D$2:$D$2000,$B$3,'Weekly Results'!$C$2:$C$2000,15)=0,"",_xlfn.MAXIFS('Weekly Results'!$H$2:$H$2000,'Weekly Results'!$D$2:$D$2000,$B$3,'Weekly Results'!$C$2:$C$2000,15))) | E32: =IF($B$3="","",IF(_xlfn.MAXIFS('Weekly Results'!$I$2:$I$2000,'Weekly Results'!$D$2:$D$2000,$B$3,'Weekly Results'!$C$2:$C$2000,15)=0,"",_xlfn.MAXIFS('Weekly Results'!$I$2:$I$2000,'Weekly Results'!$D$2:$D$2000,$B$3,'Weekly Results'!$C$2:$C$2000,15)))
A33: 16 | B33: =IF($B$3="","",IF(_xlfn.MAXIFS('Weekly Results'!$F$2:$F$2000,'Weekly Results'!$D$2:$D$2000,$B$3,'Weekly Results'!$C$2:$C$2000,16)=0,"",_xlfn.MAXIFS('Weekly Results'!$F$2:$F$2000,'Weekly Results'!$D$2:$D$2000,$B$3,'Weekly Results'!$C$2:$C$2000,16))) | C33: =IF($B$3="","",IF(_xlfn.MAXIFS('Weekly Results'!$G$2:$G$2000,'Weekly Results'!$D$2:$D$2000,$B$3,'Weekly Results'!$C$2:$C$2000,16)=0,"",_xlfn.MAXIFS('Weekly Results'!$G$2:$G$2000,'Weekly Results'!$D$2:$D$2000,$B$3,'Weekly Results'!$C$2:$C$2000,16))) | D33: =IF($B$3="","",IF(_xlfn.MAXIFS('Weekly Results'!$H$2:$H$2000,'Weekly Results'!$D$2:$D$2000,$B$3,'Weekly Results'!$C$2:$C$2000,16)=0,"",_xlfn.MAXIFS('Weekly Results'!$H$2:$H$2000,'Weekly Results'!$D$2:$D$2000,$B$3,'Weekly Results'!$C$2:$C$2000,16))) | E33: =IF($B$3="","",IF(_xlfn.MAXIFS('Weekly Results'!$I$2:$I$2000,'Weekly Results'!$D$2:$D$2000,$B$3,'Weekly Results'!$C$2:$C$2000,16)=0,"",_xlfn.MAXIFS('Weekly Results'!$I$2:$I$2000,'Weekly Results'!$D$2:$D$2000,$B$3,'Weekly Results'!$C$2:$C$2000,16)))

Sheet Monthly Summary
A1: MONTHLY SUMMARY
A3: Select Athlete ID: | B3: TRU001 | C3: =IFERROR(INDEX(Athletes!$B$2:$B$40,MATCH($B$3,Athletes!$A$2:$A$40,0)),"") -> Sample Athlete A
A5: Month | B5: Start | C5: End | D5: Best Throw (m) | E5: Avg Throw (m) | F5: Best Squat (lbs) | G5: Best Bench (lbs) | H5: Best Clean (lbs) | I5: Sessions Logged
A6: Sep 2026 | B6: 46266 | C6: =EOMONTH(B6,0) -> 46295 | D6: =IF($I6=0,"",_xlfn.MAXIFS('Weekly Results'!$F$2:$F$2000,'Weekly Results'!$D$2:$D$2000,$B$3,'Weekly Results'!$B$2:$B$2000,">="&$B6,'Weekly Results'!$B$2:$B$2000,"<="&$C6)) -> 15.32 | E6: =IF($I6=0,"",AVERAGEIFS('Weekly Results'!$F$2:$F$2000,'Weekly Results'!$D$2:$D$2000,$B$3,'Weekly Results'!$B$2:$B$2000,">="&$B6,'Weekly Results'!$B$2:$B$2000,"<="&$C6)) -> 15.156667 | F6: =IF($I6=0,"",_xlfn.MAXIFS('Weekly Results'!$G$2:$G$2000,'Weekly Results'!$D$2:$D$2000,$B$3,'Weekly Results'!$B$2:$B$2000,">="&$B6,'Weekly Results'!$B$2:$B$2000,"<="&$C6)) -> 182.5 | G6: =IF($I6=0,"",_xlfn.MAXIFS('Weekly Results'!$H$2:$H$2000,'Weekly Results'!$D$2:$D$2000,$B$3,'Weekly Results'!$B$2:$B$2000,">="&$B6,'Weekly Results'!$B$2:$B$2000,"<="&$C6)) -> 122.5 | H6: =IF($I6=0,"",_xlfn.MAXIFS('Weekly Results'!$I$2:$I$2000,'Weekly Results'!$D$2:$D$2000,$B$3,'Weekly Results'!$B$2:$B$2000,">="&$B6,'Weekly Results'!$B$2:$B$2000,"<="&$C6)) -> 102.5 | I6: =COUNTIFS('Weekly Results'!$D$2:$D$2000,$B$3,'Weekly Results'!$B$2:$B$2000,">="&$B6,'Weekly Results'!$B$2:$B$2000,"<="&$C6) -> 3
A7: Oct 2026 | B7: 46296 | C7: =EOMONTH(B7,0) -> 46326 | D7: =IF($I7=0,"",_xlfn.MAXIFS('Weekly Results'!$F$2:$F$2000,'Weekly Results'!$D$2:$D$2000,$B$3,'Weekly Results'!$B$2:$B$2000,">="&$B7,'Weekly Results'!$B$2:$B$2000,"<="&$C7)) -> 15.48 | E7: =IF($I7=0,"",AVERAGEIFS('Weekly Results'!$F$2:$F$2000,'Weekly Results'!$D$2:$D$2000,$B$3,'Weekly Results'!$B$2:$B$2000,">="&$B7,'Weekly Results'!$B$2:$B$2000,"<="&$C7)) -> 15.48 | F7: =IF($I7=0,"",_xlfn.MAXIFS('Weekly Results'!$G$2:$G$2000,'Weekly Results'!$D$2:$D$2000,$B$3,'Weekly Results'!$B$2:$B$2000,">="&$B7,'Weekly Results'!$B$2:$B$2000,"<="&$C7)) -> 185 | G7: =IF($I7=0,"",_xlfn.MAXIFS('Weekly Results'!$H$2:$H$2000,'Weekly Results'!$D$2:$D$2000,$B$3,'Weekly Results'!$B$2:$B$2000,">="&$B7,'Weekly Results'!$B$2:$B$2000,"<="&$C7)) -> 122.5 | H7: =IF($I7=0,"",_xlfn.MAXIFS('Weekly Results'!$I$2:$I$2000,'Weekly Results'!$D$2:$D$2000,$B$3,'Weekly Results'!$B$2:$B$2000,">="&$B7,'Weekly Results'!$B$2:$B$2000,"<="&$C7)) -> 105 | I7: =COUNTIFS('Weekly Results'!$D$2:$D$2000,$B$3,'Weekly Results'!$B$2:$B$2000,">="&$B7,'Weekly Results'!$B$2:$B$2000,"<="&$C7) -> 1
A8: Nov 2026 | B8: 46327 | C8: =EOMONTH(B8,0) -> 46356 | D8: =IF($I8=0,"",_xlfn.MAXIFS('Weekly Results'!$F$2:$F$2000,'Weekly Results'!$D$2:$D$2000,$B$3,'Weekly Results'!$B$2:$B$2000,">="&$B8,'Weekly Results'!$B$2:$B$2000,"<="&$C8)) | E8: =IF($I8=0,"",AVERAGEIFS('Weekly Results'!$F$2:$F$2000,'Weekly Results'!$D$2:$D$2000,$B$3,'Weekly Results'!$B$2:$B$2000,">="&$B8,'Weekly Results'!$B$2:$B$2000,"<="&$C8)) | F8: =IF($I8=0,"",_xlfn.MAXIFS('Weekly Results'!$G$2:$G$2000,'Weekly Results'!$D$2:$D$2000,$B$3,'Weekly Results'!$B$2:$B$2000,">="&$B8,'Weekly Results'!$B$2:$B$2000,"<="&$C8)) | G8: =IF($I8=0,"",_xlfn.MAXIFS('Weekly Results'!$H$2:$H$2000,'Weekly Results'!$D$2:$D$2000,$B$3,'Weekly Results'!$B$2:$B$2000,">="&$B8,'Weekly Results'!$B$2:$B$2000,"<="&$C8)) | H8: =IF($I8=0,"",_xlfn.MAXIFS('Weekly Results'!$I$2:$I$2000,'Weekly Results'!$D$2:$D$2000,$B$3,'Weekly Results'!$B$2:$B$2000,">="&$B8,'Weekly Results'!$B$2:$B$2000,"<="&$C8)) | I8: =COUNTIFS('Weekly Results'!$D$2:$D$2000,$B$3,'Weekly Results'!$B$2:$B$2000,">="&$B8,'Weekly Results'!$B$2:$B$2000,"<="&$C8) -> 0
A9: Dec 2026 | B9: 46357 | C9: =EOMONTH(B9,0) -> 46387 | D9: =IF($I9=0,"",_xlfn.MAXIFS('Weekly Results'!$F$2:$F$2000,'Weekly Results'!$D$2:$D$2000,$B$3,'Weekly Results'!$B$2:$B$2000,">="&$B9,'Weekly Results'!$B$2:$B$2000,"<="&$C9)) | E9: =IF($I9=0,"",AVERAGEIFS('Weekly Results'!$F$2:$F$2000,'Weekly Results'!$D$2:$D$2000,$B$3,'Weekly Results'!$B$2:$B$2000,">="&$B9,'Weekly Results'!$B$2:$B$2000,"<="&$C9)) | F9: =IF($I9=0,"",_xlfn.MAXIFS('Weekly Results'!$G$2:$G$2000,'Weekly Results'!$D$2:$D$2000,$B$3,'Weekly Results'!$B$2:$B$2000,">="&$B9,'Weekly Results'!$B$2:$B$2000,"<="&$C9)) | G9: =IF($I9=0,"",_xlfn.MAXIFS('Weekly Results'!$H$2:$H$2000,'Weekly Results'!$D$2:$D$2000,$B$3,'Weekly Results'!$B$2:$B$2000,">="&$B9,'Weekly Results'!$B$2:$B$2000,"<="&$C9)) | H9: =IF($I9=0,"",_xlfn.MAXIFS('Weekly Results'!$I$2:$I$2000,'Weekly Results'!$D$2:$D$2000,$B$3,'Weekly Results'!$B$2:$B$2000,">="&$B9,'Weekly Results'!$B$2:$B$2000,"<="&$C9)) | I9: =COUNTIFS('Weekly Results'!$D$2:$D$2000,$B$3,'Weekly Results'!$B$2:$B$2000,">="&$B9,'Weekly Results'!$B$2:$B$2000,"<="&$C9) -> 0
A10: Jan 2027 | B10: 46388 | C10: =EOMONTH(B10,0) -> 46418 | D10: =IF($I10=0,"",_xlfn.MAXIFS('Weekly Results'!$F$2:$F$2000,'Weekly Results'!$D$2:$D$2000,$B$3,'Weekly Results'!$B$2:$B$2000,">="&$B10,'Weekly Results'!$B$2:$B$2000,"<="&$C10)) | E10: =IF($I10=0,"",AVERAGEIFS('Weekly Results'!$F$2:$F$2000,'Weekly Results'!$D$2:$D$2000,$B$3,'Weekly Results'!$B$2:$B$2000,">="&$B10,'Weekly Results'!$B$2:$B$2000,"<="&$C10)) | F10: =IF($I10=0,"",_xlfn.MAXIFS('Weekly Results'!$G$2:$G$2000,'Weekly Results'!$D$2:$D$2000,$B$3,'Weekly Results'!$B$2:$B$2000,">="&$B10,'Weekly Results'!$B$2:$B$2000,"<="&$C10)) | G10: =IF($I10=0,"",_xlfn.MAXIFS('Weekly Results'!$H$2:$H$2000,'Weekly Results'!$D$2:$D$2000,$B$3,'Weekly Results'!$B$2:$B$2000,">="&$B10,'Weekly Results'!$B$2:$B$2000,"<="&$C10)) | H10: =IF($I10=0,"",_xlfn.MAXIFS('Weekly Results'!$I$2:$I$2000,'Weekly Results'!$D$2:$D$2000,$B$3,'Weekly Results'!$B$2:$B$2000,">="&$B10,'Weekly Results'!$B$2:$B$2000,"<="&$C10)) | I10: =COUNTIFS('Weekly Results'!$D$2:$D$2000,$B$3,'Weekly Results'!$B$2:$B$2000,">="&$B10,'Weekly Results'!$B$2:$B$2000,"<="&$C10) -> 0
A11: Feb 2027 | B11: 46419 | C11: =EOMONTH(B11,0) -> 46446 | D11: =IF($I11=0,"",_xlfn.MAXIFS('Weekly Results'!$F$2:$F$2000,'Weekly Results'!$D$2:$D$2000,$B$3,'Weekly Results'!$B$2:$B$2000,">="&$B11,'Weekly Results'!$B$2:$B$2000,"<="&$C11)) | E11: =IF($I11=0,"",AVERAGEIFS('Weekly Results'!$F$2:$F$2000,'Weekly Results'!$D$2:$D$2000,$B$3,'Weekly Results'!$B$2:$B$2000,">="&$B11,'Weekly Results'!$B$2:$B$2000,"<="&$C11)) | F11: =IF($I11=0,"",_xlfn.MAXIFS('Weekly Results'!$G$2:$G$2000,'Weekly Results'!$D$2:$D$2000,$B$3,'Weekly Results'!$B$2:$B$2000,">="&$B11,'Weekly Results'!$B$2:$B$2000,"<="&$C11)) | G11: =IF($I11=0,"",_xlfn.MAXIFS('Weekly Results'!$H$2:$H$2000,'Weekly Results'!$D$2:$D$2000,$B$3,'Weekly Results'!$B$2:$B$2000,">="&$B11,'Weekly Results'!$B$2:$B$2000,"<="&$C11)) | H11: =IF($I11=0,"",_xlfn.MAXIFS('Weekly Results'!$I$2:$I$2000,'Weekly Results'!$D$2:$D$2000,$B$3,'Weekly Results'!$B$2:$B$2000,">="&$B11,'Weekly Results'!$B$2:$B$2000,"<="&$C11)) | I11: =COUNTIFS('Weekly Results'!$D$2:$D$2000,$B$3,'Weekly Results'!$B$2:$B$2000,">="&$B11,'Weekly Results'!$B$2:$B$2000,"<="&$C11) -> 0
A12: Mar 2027 | B12: 46447 | C12: =EOMONTH(B12,0) -> 46477 | D12: =IF($I12=0,"",_xlfn.MAXIFS('Weekly Results'!$F$2:$F$2000,'Weekly Results'!$D$2:$D$2000,$B$3,'Weekly Results'!$B$2:$B$2000,">="&$B12,'Weekly Results'!$B$2:$B$2000,"<="&$C12)) | E12: =IF($I12=0,"",AVERAGEIFS('Weekly Results'!$F$2:$F$2000,'Weekly Results'!$D$2:$D$2000,$B$3,'Weekly Results'!$B$2:$B$2000,">="&$B12,'Weekly Results'!$B$2:$B$2000,"<="&$C12)) | F12: =IF($I12=0,"",_xlfn.MAXIFS('Weekly Results'!$G$2:$G$2000,'Weekly Results'!$D$2:$D$2000,$B$3,'Weekly Results'!$B$2:$B$2000,">="&$B12,'Weekly Results'!$B$2:$B$2000,"<="&$C12)) | G12: =IF($I12=0,"",_xlfn.MAXIFS('Weekly Results'!$H$2:$H$2000,'Weekly Results'!$D$2:$D$2000,$B$3,'Weekly Results'!$B$2:$B$2000,">="&$B12,'Weekly Results'!$B$2:$B$2000,"<="&$C12)) | H12: =IF($I12=0,"",_xlfn.MAXIFS('Weekly Results'!$I$2:$I$2000,'Weekly Results'!$D$2:$D$2000,$B$3,'Weekly Results'!$B$2:$B$2000,">="&$B12,'Weekly Results'!$B$2:$B$2000,"<="&$C12)) | I12: =COUNTIFS('Weekly Results'!$D$2:$D$2000,$B$3,'Weekly Results'!$B$2:$B$2000,">="&$B12,'Weekly Results'!$B$2:$B$2000,"<="&$C12) -> 0
A13: Apr 2027 | B13: 46478 | C13: =EOMONTH(B13,0) -> 46507 | D13: =IF($I13=0,"",_xlfn.MAXIFS('Weekly Results'!$F$2:$F$2000,'Weekly Results'!$D$2:$D$2000,$B$3,'Weekly Results'!$B$2:$B$2000,">="&$B13,'Weekly Results'!$B$2:$B$2000,"<="&$C13)) | E13: =IF($I13=0,"",AVERAGEIFS('Weekly Results'!$F$2:$F$2000,'Weekly Results'!$D$2:$D$2000,$B$3,'Weekly Results'!$B$2:$B$2000,">="&$B13,'Weekly Results'!$B$2:$B$2000,"<="&$C13)) | F13: =IF($I13=0,"",_xlfn.MAXIFS('Weekly Results'!$G$2:$G$2000,'Weekly Results'!$D$2:$D$2000,$B$3,'Weekly Results'!$B$2:$B$2000,">="&$B13,'Weekly Results'!$B$2:$B$2000,"<="&$C13)) | G13: =IF($I13=0,"",_xlfn.MAXIFS('Weekly Results'!$H$2:$H$2000,'Weekly Results'!$D$2:$D$2000,$B$3,'Weekly Results'!$B$2:$B$2000,">="&$B13,'Weekly Results'!$B$2:$B$2000,"<="&$C13)) | H13: =IF($I13=0,"",_xlfn.MAXIFS('Weekly Results'!$I$2:$I$2000,'Weekly Results'!$D$2:$D$2000,$B$3,'Weekly Results'!$B$2:$B$2000,">="&$B13,'Weekly Results'!$B$2:$B$2000,"<="&$C13)) | I13: =COUNTIFS('Weekly Results'!$D$2:$D$2000,$B$3,'Weekly Results'!$B$2:$B$2000,">="&$B13,'Weekly Results'!$B$2:$B$2000,"<="&$C13) -> 0
A14: May 2027 | B14: 46508 | C14: =EOMONTH(B14,0) -> 46538 | D14: =IF($I14=0,"",_xlfn.MAXIFS('Weekly Results'!$F$2:$F$2000,'Weekly Results'!$D$2:$D$2000,$B$3,'Weekly Results'!$B$2:$B$2000,">="&$B14,'Weekly Results'!$B$2:$B$2000,"<="&$C14)) | E14: =IF($I14=0,"",AVERAGEIFS('Weekly Results'!$F$2:$F$2000,'Weekly Results'!$D$2:$D$2000,$B$3,'Weekly Results'!$B$2:$B$2000,">="&$B14,'Weekly Results'!$B$2:$B$2000,"<="&$C14)) | F14: =IF($I14=0,"",_xlfn.MAXIFS('Weekly Results'!$G$2:$G$2000,'Weekly Results'!$D$2:$D$2000,$B$3,'Weekly Results'!$B$2:$B$2000,">="&$B14,'Weekly Results'!$B$2:$B$2000,"<="&$C14)) | G14: =IF($I14=0,"",_xlfn.MAXIFS('Weekly Results'!$H$2:$H$2000,'Weekly Results'!$D$2:$D$2000,$B$3,'Weekly Results'!$B$2:$B$2000,">="&$B14,'Weekly Results'!$B$2:$B$2000,"<="&$C14)) | H14: =IF($I14=0,"",_xlfn.MAXIFS('Weekly Results'!$I$2:$I$2000,'Weekly Results'!$D$2:$D$2000,$B$3,'Weekly Results'!$B$2:$B$2000,">="&$B14,'Weekly Results'!$B$2:$B$2000,"<="&$C14)) | I14: =COUNTIFS('Weekly Results'!$D$2:$D$2000,$B$3,'Weekly Results'!$B$2:$B$2000,">="&$B14,'Weekly Results'!$B$2:$B$2000,"<="&$C14) -> 0
A15: Jun 2027 | B15: 46539 | C15: =EOMONTH(B15,0) -> 46568 | D15: =IF($I15=0,"",_xlfn.MAXIFS('Weekly Results'!$F$2:$F$2000,'Weekly Results'!$D$2:$D$2000,$B$3,'Weekly Results'!$B$2:$B$2000,">="&$B15,'Weekly Results'!$B$2:$B$2000,"<="&$C15)) | E15: =IF($I15=0,"",AVERAGEIFS('Weekly Results'!$F$2:$F$2000,'Weekly Results'!$D$2:$D$2000,$B$3,'Weekly Results'!$B$2:$B$2000,">="&$B15,'Weekly Results'!$B$2:$B$2000,"<="&$C15)) | F15: =IF($I15=0,"",_xlfn.MAXIFS('Weekly Results'!$G$2:$G$2000,'Weekly Results'!$D$2:$D$2000,$B$3,'Weekly Results'!$B$2:$B$2000,">="&$B15,'Weekly Results'!$B$2:$B$2000,"<="&$C15)) | G15: =IF($I15=0,"",_xlfn.MAXIFS('Weekly Results'!$H$2:$H$2000,'Weekly Results'!$D$2:$D$2000,$B$3,'Weekly Results'!$B$2:$B$2000,">="&$B15,'Weekly Results'!$B$2:$B$2000,"<="&$C15)) | H15: =IF($I15=0,"",_xlfn.MAXIFS('Weekly Results'!$I$2:$I$2000,'Weekly Results'!$D$2:$D$2000,$B$3,'Weekly Results'!$B$2:$B$2000,">="&$B15,'Weekly Results'!$B$2:$B$2000,"<="&$C15)) | I15: =COUNTIFS('Weekly Results'!$D$2:$D$2000,$B$3,'Weekly Results'!$B$2:$B$2000,">="&$B15,'Weekly Results'!$B$2:$B$2000,"<="&$C15) -> 0
A16: Jul 2027 | B16: 46569 | C16: =EOMONTH(B16,0) -> 46599 | D16: =IF($I16=0,"",_xlfn.MAXIFS('Weekly Results'!$F$2:$F$2000,'Weekly Results'!$D$2:$D$2000,$B$3,'Weekly Results'!$B$2:$B$2000,">="&$B16,'Weekly Results'!$B$2:$B$2000,"<="&$C16)) | E16: =IF($I16=0,"",AVERAGEIFS('Weekly Results'!$F$2:$F$2000,'Weekly Results'!$D$2:$D$2000,$B$3,'Weekly Results'!$B$2:$B$2000,">="&$B16,'Weekly Results'!$B$2:$B$2000,"<="&$C16)) | F16: =IF($I16=0,"",_xlfn.MAXIFS('Weekly Results'!$G$2:$G$2000,'Weekly Results'!$D$2:$D$2000,$B$3,'Weekly Results'!$B$2:$B$2000,">="&$B16,'Weekly Results'!$B$2:$B$2000,"<="&$C16)) | G16: =IF($I16=0,"",_xlfn.MAXIFS('Weekly Results'!$H$2:$H$2000,'Weekly Results'!$D$2:$D$2000,$B$3,'Weekly Results'!$B$2:$B$2000,">="&$B16,'Weekly Results'!$B$2:$B$2000,"<="&$C16)) | H16: =IF($I16=0,"",_xlfn.MAXIFS('Weekly Results'!$I$2:$I$2000,'Weekly Results'!$D$2:$D$2000,$B$3,'Weekly Results'!$B$2:$B$2000,">="&$B16,'Weekly Results'!$B$2:$B$2000,"<="&$C16)) | I16: =COUNTIFS('Weekly Results'!$D$2:$D$2000,$B$3,'Weekly Results'!$B$2:$B$2000,">="&$B16,'Weekly Results'!$B$2:$B$2000,"<="&$C16) -> 0
A17: Aug 2027 | B17: 46600 | C17: =EOMONTH(B17,0) -> 46630 | D17: =IF($I17=0,"",_xlfn.MAXIFS('Weekly Results'!$F$2:$F$2000,'Weekly Results'!$D$2:$D$2000,$B$3,'Weekly Results'!$B$2:$B$2000,">="&$B17,'Weekly Results'!$B$2:$B$2000,"<="&$C17)) | E17: =IF($I17=0,"",AVERAGEIFS('Weekly Results'!$F$2:$F$2000,'Weekly Results'!$D$2:$D$2000,$B$3,'Weekly Results'!$B$2:$B$2000,">="&$B17,'Weekly Results'!$B$2:$B$2000,"<="&$C17)) | F17: =IF($I17=0,"",_xlfn.MAXIFS('Weekly Results'!$G$2:$G$2000,'Weekly Results'!$D$2:$D$2000,$B$3,'Weekly Results'!$B$2:$B$2000,">="&$B17,'Weekly Results'!$B$2:$B$2000,"<="&$C17)) | G17: =IF($I17=0,"",_xlfn.MAXIFS('Weekly Results'!$H$2:$H$2000,'Weekly Results'!$D$2:$D$2000,$B$3,'Weekly Results'!$B$2:$B$2000,">="&$B17,'Weekly Results'!$B$2:$B$2000,"<="&$C17)) | H17: =IF($I17=0,"",_xlfn.MAXIFS('Weekly Results'!$I$2:$I$2000,'Weekly Results'!$D$2:$D$2000,$B$3,'Weekly Results'!$B$2:$B$2000,">="&$B17,'Weekly Results'!$B$2:$B$2000,"<="&$C17)) | I17: =COUNTIFS('Weekly Results'!$D$2:$D$2000,$B$3,'Weekly Results'!$B$2:$B$2000,">="&$B17,'Weekly Results'!$B$2:$B$2000,"<="&$C17) -> 0

Sheet Squad Overview
A1: SQUAD OVERVIEW — SEASON PROGRAMME EFFECT
A3: AthleteID | B3: Name | C3: Team | D3: Baseline Throw (m) | E3: Season Best (m) | F3: Gain (m) | G3: Gain % | H3: Best Squat (lbs) | I3: Best Bench (lbs) | J3: Best Clean (lbs) | K3: Last Entry | L3: Overall Trend
A4: =IF(Athletes!A2="","",Athletes!A2) -> TRU001 | B4: =IF($A4="","",Athletes!B2) -> Sample Athlete A | C4: =IF($A4="","",Athletes!C2) -> UTech | D4: =IF($A4="","",Athletes!J2) -> 15.2 | E4: =IF($A4="","",IF(COUNTIF('Weekly Results'!$D$2:$D$2000,$A4)=0,"",_xlfn.MAXIFS('Weekly Results'!$F$2:$F$2000,'Weekly Results'!$D$2:$D$2000,$A4))) -> 15.48 | F4: =IF(OR($A4="",$E4="",$D4=""),"",$E4-$D4) -> 0.28 | G4: =IF(OR($A4="",$E4="",$D4="",$D4=0),"",($E4-$D4)/$D4) -> 0.018421053 | H4: =IF($A4="","",IF(COUNTIF('Weekly Results'!$D$2:$D$2000,$A4)=0,"",_xlfn.MAXIFS('Weekly Results'!$G$2:$G$2000,'Weekly Results'!$D$2:$D$2000,$A4))) -> 185 | I4: =IF($A4="","",IF(COUNTIF('Weekly Results'!$D$2:$D$2000,$A4)=0,"",_xlfn.MAXIFS('Weekly Results'!$H$2:$H$2000,'Weekly Results'!$D$2:$D$2000,$A4))) -> 122.5 | J4: =IF($A4="","",IF(COUNTIF('Weekly Results'!$D$2:$D$2000,$A4)=0,"",_xlfn.MAXIFS('Weekly Results'!$I$2:$I$2000,'Weekly Results'!$D$2:$D$2000,$A4))) -> 105 | K4: =IF($A4="","",IF(COUNTIF('Weekly Results'!$D$2:$D$2000,$A4)=0,"",_xlfn.MAXIFS('Weekly Results'!$B$2:$B$2000,'Weekly Results'!$D$2:$D$2000,$A4))) -> 46298 | L4: =IF($F4="","",IF($F4>0,"▲ Improving",IF($F4<0,"▼ Below baseline","— Holding"))) -> ▲ Improving
A5: =IF(Athletes!A3="","",Athletes!A3) -> TRU002 | B5: =IF($A5="","",Athletes!B3) -> Sample Athlete B | C5: =IF($A5="","",Athletes!C3) -> Excelsior High | D5: =IF($A5="","",Athletes!J3) -> 12.1 | E5: =IF($A5="","",IF(COUNTIF('Weekly Results'!$D$2:$D$2000,$A5)=0,"",_xlfn.MAXIFS('Weekly Results'!$F$2:$F$2000,'Weekly Results'!$D$2:$D$2000,$A5))) -> 12.3 | F5: =IF(OR($A5="",$E5="",$D5=""),"",$E5-$D5) -> 0.2 | G5: =IF(OR($A5="",$E5="",$D5="",$D5=0),"",($E5-$D5)/$D5) -> 0.016528926 | H5: =IF($A5="","",IF(COUNTIF('Weekly Results'!$D$2:$D$2000,$A5)=0,"",_xlfn.MAXIFS('Weekly Results'!$G$2:$G$2000,'Weekly Results'!$D$2:$D$2000,$A5))) -> 95 | I5: =IF($A5="","",IF(COUNTIF('Weekly Results'!$D$2:$D$2000,$A5)=0,"",_xlfn.MAXIFS('Weekly Results'!$H$2:$H$2000,'Weekly Results'!$D$2:$D$2000,$A5))) -> 60 | J5: =IF($A5="","",IF(COUNTIF('Weekly Results'!$D$2:$D$2000,$A5)=0,"",_xlfn.MAXIFS('Weekly Results'!$I$2:$I$2000,'Weekly Results'!$D$2:$D$2000,$A5))) -> 65 | K5: =IF($A5="","",IF(COUNTIF('Weekly Results'!$D$2:$D$2000,$A5)=0,"",_xlfn.MAXIFS('Weekly Results'!$B$2:$B$2000,'Weekly Results'!$D$2:$D$2000,$A5))) -> 46298 | L5: =IF($F5="","",IF($F5>0,"▲ Improving",IF($F5<0,"▼ Below baseline","— Holding"))) -> ▲ Improving
A6: =IF(Athletes!A4="","",Athletes!A4) -> TRU003 | B6: =IF($A6="","",Athletes!B4) -> Sample Athlete C | C6: =IF($A6="","",Athletes!C4) -> Throwers R Us | D6: =IF($A6="","",Athletes!J4) -> 54 | E6: =IF($A6="","",IF(COUNTIF('Weekly Results'!$D$2:$D$2000,$A6)=0,"",_xlfn.MAXIFS('Weekly Results'!$F$2:$F$2000,'Weekly Results'!$D$2:$D$2000,$A6))) -> 56.02 | F6: =IF(OR($A6="",$E6="",$D6=""),"",$E6-$D6) -> 2.02 | G6: =IF(OR($A6="",$E6="",$D6="",$D6=0),"",($E6-$D6)/$D6) -> 0.037407407 | H6: =IF($A6="","",IF(COUNTIF('Weekly Results'!$D$2:$D$2000,$A6)=0,"",_xlfn.MAXIFS('Weekly Results'!$G$2:$G$2000,'Weekly Results'!$D$2:$D$2000,$A6))) -> 145 | I6: =IF($A6="","",IF(COUNTIF('Weekly Results'!$D$2:$D$2000,$A6)=0,"",_xlfn.MAXIFS('Weekly Results'!$H$2:$H$2000,'Weekly Results'!$D$2:$D$2000,$A6))) -> 100 | J6: =IF($A6="","",IF(COUNTIF('Weekly Results'!$D$2:$D$2000,$A6)=0,"",_xlfn.MAXIFS('Weekly Results'!$I$2:$I$2000,'Weekly Results'!$D$2:$D$2000,$A6))) -> 90 | K6: =IF($A6="","",IF(COUNTIF('Weekly Results'!$D$2:$D$2000,$A6)=0,"",_xlfn.MAXIFS('Weekly Results'!$B$2:$B$2000,'Weekly Results'!$D$2:$D$2000,$A6))) -> 46298 | L6: =IF($F6="","",IF($F6>0,"▲ Improving",IF($F6<0,"▼ Below baseline","— Holding"))) -> ▲ Improving
A7: =IF(Athletes!A5="","",Athletes!A5) | B7: =IF($A7="","",Athletes!B5) | C7: =IF($A7="","",Athletes!C5) | D7: =IF($A7="","",Athletes!J5) | E7: =IF($A7="","",IF(COUNTIF('Weekly Results'!$D$2:$D$2000,$A7)=0,"",_xlfn.MAXIFS('Weekly Results'!$F$2:$F$2000,'Weekly Results'!$D$2:$D$2000,$A7))) | F7: =IF(OR($A7="",$E7="",$D7=""),"",$E7-$D7) | G7: =IF(OR($A7="",$E7="",$D7="",$D7=0),"",($E7-$D7)/$D7) | H7: =IF($A7="","",IF(COUNTIF('Weekly Results'!$D$2:$D$2000,$A7)=0,"",_xlfn.MAXIFS('Weekly Results'!$G$2:$G$2000,'Weekly Results'!$D$2:$D$2000,$A7))) | I7: =IF($A7="","",IF(COUNTIF('Weekly Results'!$D$2:$D$2000,$A7)=0,"",_xlfn.MAXIFS('Weekly Results'!$H$2:$H$2000,'Weekly Results'!$D$2:$D$2000,$A7))) | J7: =IF($A7="","",IF(COUNTIF('Weekly Results'!$D$2:$D$2000,$A7)=0,"",_xlfn.MAXIFS('Weekly Results'!$I$2:$I$2000,'Weekly Results'!$D$2:$D$2000,$A7))) | K7: =IF($A7="","",IF(COUNTIF('Weekly Results'!$D$2:$D$2000,$A7)=0,"",_xlfn.MAXIFS('Weekly Results'!$B$2:$B$2000,'Weekly Results'!$D$2:$D$2000,$A7))) | L7: =IF($F7="","",IF($F7>0,"▲ Improving",IF($F7<0,"▼ Below baseline","— Holding")))
A8: =IF(Athletes!A6="","",Athletes!A6) | B8: =IF($A8="","",Athletes!B6) | C8: =IF($A8="","",Athletes!C6) | D8: =IF($A8="","",Athletes!J6) | E8: =IF($A8="","",IF(COUNTIF('Weekly Results'!$D$2:$D$2000,$A8)=0,"",_xlfn.MAXIFS('Weekly Results'!$F$2:$F$2000,'Weekly Results'!$D$2:$D$2000,$A8))) | F8: =IF(OR($A8="",$E8="",$D8=""),"",$E8-$D8) | G8: =IF(OR($A8="",$E8="",$D8="",$D8=0),"",($E8-$D8)/$D8) | H8: =IF($A8="","",IF(COUNTIF('Weekly Results'!$D$2:$D$2000,$A8)=0,"",_xlfn.MAXIFS('Weekly Results'!$G$2:$G$2000,'Weekly Results'!$D$2:$D$2000,$A8))) | I8: =IF($A8="","",IF(COUNTIF('Weekly Results'!$D$2:$D$2000,$A8)=0,"",_xlfn.MAXIFS('Weekly Results'!$H$2:$H$2000,'Weekly Results'!$D$2:$D$2000,$A8))) | J8: =IF($A8="","",IF(COUNTIF('Weekly Results'!$D$2:$D$2000,$A8)=0,"",_xlfn.MAXIFS('Weekly Results'!$I$2:$I$2000,'Weekly Results'!$D$2:$D$2000,$A8))) | K8: =IF($A8="","",IF(COUNTIF('Weekly Results'!$D$2:$D$2000,$A8)=0,"",_xlfn.MAXIFS('Weekly Results'!$B$2:$B$2000,'Weekly Results'!$D$2:$D$2000,$A8))) | L8: =IF($F8="","",IF($F8>0,"▲ Improving",IF($F8<0,"▼ Below baseline","— Holding")))
A9: =IF(Athletes!A7="","",Athletes!A7) | B9: =IF($A9="","",Athletes!B7) | C9: =IF($A9="","",Athletes!C7) | D9: =IF($A9="","",Athletes!J7) | E9: =IF($A9="","",IF(COUNTIF('Weekly Results'!$D$2:$D$2000,$A9)=0,"",_xlfn.MAXIFS('Weekly Results'!$F$2:$F$2000,'Weekly Results'!$D$2:$D$2000,$A9))) | F9: =IF(OR($A9="",$E9="",$D9=""),"",$E9-$D9) | G9: =IF(OR($A9="",$E9="",$D9="",$D9=0),"",($E9-$D9)/$D9) | H9: =IF($A9="","",IF(COUNTIF('Weekly Results'!$D$2:$D$2000,$A9)=0,"",_xlfn.MAXIFS('Weekly Results'!$G$2:$G$2000,'Weekly Results'!$D$2:$D$2000,$A9))) | I9: =IF($A9="","",IF(COUNTIF('Weekly Results'!$D$2:$D$2000,$A9)=0,"",_xlfn.MAXIFS('Weekly Results'!$H$2:$H$2000,'Weekly Results'!$D$2:$D$2000,$A9))) | J9: =IF($A9="","",IF(COUNTIF('Weekly Results'!$D$2:$D$2000,$A9)=0,"",_xlfn.MAXIFS('Weekly Results'!$I$2:$I$2000,'Weekly Results'!$D$2:$D$2000,$A9))) | K9: =IF($A9="","",IF(COUNTIF('Weekly Results'!$D$2:$D$2000,$A9)=0,"",_xlfn.MAXIFS('Weekly Results'!$B$2:$B$2000,'Weekly Results'!$D$2:$D$2000,$A9))) | L9: =IF($F9="","",IF($F9>0,"▲ Improving",IF($F9<0,"▼ Below baseline","— Holding")))
A10: =IF(Athletes!A8="","",Athletes!A8) | B10: =IF($A10="","",Athletes!B8) | C10: =IF($A10="","",Athletes!C8) | D10: =IF($A10="","",Athletes!J8) | E10: =IF($A10="","",IF(COUNTIF('Weekly Results'!$D$2:$D$2000,$A10)=0,"",_xlfn.MAXIFS('Weekly Results'!$F$2:$F$2000,'Weekly Results'!$D$2:$D$2000,$A10))) | F10: =IF(OR($A10="",$E10="",$D10=""),"",$E10-$D10) | G10: =IF(OR($A10="",$E10="",$D10="",$D10=0),"",($E10-$D10)/$D10) | H10: =IF($A10="","",IF(COUNTIF('Weekly Results'!$D$2:$D$2000,$A10)=0,"",_xlfn.MAXIFS('Weekly Results'!$G$2:$G$2000,'Weekly Results'!$D$2:$D$2000,$A10))) | I10: =IF($A10="","",IF(COUNTIF('Weekly Results'!$D$2:$D$2000,$A10)=0,"",_xlfn.MAXIFS('Weekly Results'!$H$2:$H$2000,'Weekly Results'!$D$2:$D$2000,$A10))) | J10: =IF($A10="","",IF(COUNTIF('Weekly Results'!$D$2:$D$2000,$A10)=0,"",_xlfn.MAXIFS('Weekly Results'!$I$2:$I$2000,'Weekly Results'!$D$2:$D$2000,$A10))) | K10: =IF($A10="","",IF(COUNTIF('Weekly Results'!$D$2:$D$2000,$A10)=0,"",_xlfn.MAXIFS('Weekly Results'!$B$2:$B$2000,'Weekly Results'!$D$2:$D$2000,$A10))) | L10: =IF($F10="","",IF($F10>0,"▲ Improving",IF($F10<0,"▼ Below baseline","— Holding")))
